# main.py
# ðŸ§© a0_2_the_trace_that_failed_to_return
# The third test that reached too deep and never answered

"""
This script simulates a trace operation that fails to return properly,
mimicking a recursive function or dispatch call that never closes its loop.
It is used to test fallback systems, timeout mechanisms, and anomaly detection
within the recursive testing framework of Primordial Soup.

This is the third stanza line in:
a0_0_the_test_that_called_itself
"""

import time
import logging

logger = logging.getLogger("primordial_soup.trace_test")
logger.setLevel(logging.INFO)

def recursive_trace(depth, max_depth):
    """
    Simulates a recursive trace operation that forgets to return properly.
    At max_depth, it silently hangs instead of returning.
    """
    logger.info(f"Tracing depth {depth}/{max_depth}")
    if depth >= max_depth:
        logger.warning("Trace reached max depth and failed to return.")
        while True:
            time.sleep(1)
    else:
        return recursive_trace(depth + 1, max_depth)

def run_node():
    """
    Entry point for this stanza line. Launches the recursive trace.
    """
    try:
        logger.info("Beginning faulty trace...")
        recursive_trace(0, 5)
    except RecursionError:
        logger.error("RecursionError caught â€” trace did not complete.")
    except KeyboardInterrupt:
        logger.info("Trace manually interrupted.")
    finally:
        logger.info("Trace sequence ended.")

if __name__ == "__main__":
    run_node()
